<?xml version="1.0" encoding="utf-8"?>
<mujoco model="qube">
    <compiler angle="radian" coordinate="local" meshdir="../meshes/" inertiafromgeom="auto"/>
    <option gravity="0 0 -9.81" integrator="RK4"/>

    <asset>
        <include file="shared_assets.xml"/>
        <texture builtin="flat" name="texbody" height="1024" width="1024" rgb1="0 0 0" type="2d"/>
        <texture builtin="flat" name="texfloor" height="1024" width="1024" rgb1="1 1 1" type="2d"/>
        <texture builtin="flat" name="texred" height="1024" width="1024" rgb1="0.698 0.1333 0.1333" type="2d"/>
        <texture builtin="flat" name="texsilver" height="512" width="512" rgb1="0.7529 0.7529 0.7529" type="2d"/>
		<material name="bodyMat" shininess="0.1" specular="0.75" texture="texbody"/>
        <material name="floorMat" shininess="0.3" specular="0.75" texture="texfloor"/>
        <material name="redMat" shininess="0.9" specular="1.0" texture="texred"/>
        <material name="silverMat" shininess="0.3" specular="0.75" texture="texsilver"/>
    </asset>

    <visual>
        <global fovy="45" />
    </visual>

    <worldbody>
        <light diffuse=".8 .8 .8" dir="0 0 -1" directional="false" pos="0.051036 -0.032181818 0.5" specular="0.9 0.9 0.9" castshadow="true"/>

        <camera pos="-5 -5 15" name="view" euler="-30 0 -45"/>

        <geom conaffinity="0" contype="0" name="ground" pos="0 0 0" size="5 5 1" type="plane" material="floorMat"/>

        <body name="qube0:body" pos="0 0 0">
            <inertial diaginertia="0 0 0" mass="0" pos="0 0 0" />
			<geom contype="0" mesh="qube0:base" name="qube0:base" type="mesh" material="bodyMat"/>

            <body name="motor" pos="0.051036 -0.052181818 0.106909091">
				<joint axis="0 0 1" name="base_motor" range="-90 90" type="hinge" damping="4.95104048e-04"/>
                <geom contype="0" mesh="qube0:motor" name="qube0:motor" type="mesh" material="redMat"/>

                <body name="arm" pos="0 -0.0665 0.02036363636">
				    <geom mesh="qube0:arm" name="qube0:arm" type="mesh" material="silverMat" mass="0.095"/>

                    <body name="pole" pos="0 -0.019 0">
				        <joint axis="0 1 0" name="arm_pole" range="-90 90" type="hinge" damping="3.21397834e-05"/>
				        <geom mesh="qube0:pole" name="qube0:pole" type="mesh" material="redMat" mass="0.024"/>
                        <!-- <inertial pos="0.0 0.0 2.293429" mass="0.024" diaginertia="0.009411 1.072831 1.072943" /> -->
                    </body>
                </body>
			</body>
		</body>
    </worldbody>

    <actuator>
        <motor joint="base_motor" name="motor_rotation" ctrllimited="true" ctrlrange="-18 18"/>
    </actuator>
</mujoco>